Workbook

Sheet Key Information
A1: Key: | B1: Provided data
B3: New Business Assumption | G3: Premium Increase and Decrement Assumptions
G4: based on assumed average age and assumed average policy duration for each projection year, before benefit indexation
B5: For the purposes of the projection, assume there is no new business written on or after 1 July 2019.
F6: Year | G6: Premium Increase (p.a.) | H6: Claim Incidence Rate (Annual) | I6: Lapse Rate (Annual)
B7: Assumption on Timing of Cash Flow
F8: 1 | G8: 0.015 | H8: 0.0018 | I8: 0.088
B9: For the purposes of the projection, assume that: | F9: 2 | G9: 0.0156 | H9: 0.0018 | I9: 0.09
B10: - Premiums are received annually in advance (on every 1 July). | F10: 3 | G10: 0.016224 | H10: 0.0019 | I10: 0.09
B11: - Expense and commissions are incurred annually in advance (on every 1 July). | F11: 4 | G11: 0.01687296 | H11: 0.0019 | I11: 0.091
B12: - Claims are incurred and paid annually in arrears (on every 30 June). | F12: 5 | G12: 0.017547878 | H12: 0.0019 | I12: 0.092
F13: 6 | G13: 0.018249794 | H13: 0.002 | I13: 0.092
B14: Discount Rate Assumption | F14: 7 | G14: 0.018979785 | H14: 0.002 | I14: 0.093
F15: 8 | G15: 0.019738977 | H15: 0.0021 | I15: 0.094
B16: Discount Rate (p.a.) | C16: 0.03 | F16: 9 | G16: 0.020528536 | H16: 0.0021 | I16: 0.095
F17: 10 | G17: 0.021349677 | H17: 0.0021 | I17: 0.096
B18: Inflation Assumptions | F18: 11 | G18: 0.022203664 | H18: 0.0022 | I18: 0.097
F19: 12 | G19: 0.023091811 | H19: 0.0022 | I19: 0.098
B20: Expense Inflation (p.a.) | C20: 0.03 | F20: 13 | G20: 0.024015483 | H20: 0.0023 | I20: 0.099
B21: Benefit Indexation (p.a.) | C21: 0.02 | F21: 14 | G21: 0.024976103 | H21: 0.0023 | I21: 0.1
F22: 15 | G22: 0.025975147 | H22: 0.0024 | I22: 0.101
B23: Expense Assumptions | F23: 16 | G23: 0.027014153 | H23: 0.0024 | I23: 0.102
F24: 17 | G24: 0.028094719 | H24: 0.0025 | I24: 0.103
B25: Gross Renewal Expense | C25: 18000000 | D25: for year ending 30 June 2020 | F25: 18 | G25: 0.029218507 | H25: 0.0025 | I25: 0.104
B26: (Gross Renewal Expense is incurred annually in advance on every 1 July, based on the proportion of policies in-force remaining at that time.) | F26: 19 | G26: 0.030387248 | H26: 0.0026 | I26: 0.105
F27: 20 | G27: 0.031602738 | H27: 0.0026 | I27: 0.106
B28: Commission Assumptions | F28: 21 | G28: 0.032866847 | H28: 0.0027 | I28: 0.107
F29: 22 | G29: 0.034181521 | H29: 0.0027 | I29: 0.108
B30: Gross Renewal Commission | C30: 0.05 | D30: as % of Gross Premium | F30: 23 | G30: 0.035548782 | H30: 0.0027 | I30: 0.11
F31: 24 | G31: 0.036970733 | H31: 0.0028 | I31: 0.111
B32: Profit Carrier Information | F32: 25 | G32: 0.038449562 | H32: 0.0029 | I32: 0.112
B33: Use expected gross premiums as the profit carrier. | F33: 26 | G33: 0.039987545 | H33: 0.003 | I33: 0.113
F34: 27 | G34: 0.041587047 | H34: 0.003 | I34: 0.114
F35: 28 | G35: 0.043250529 | H35: 0.0031 | I35: 0.115
F36: 29 | G36: 0.04498055 | H36: 0.0031 | I36: 0.116
B37: Reinsurance Information | F37: 30 | G37: 0.046779772 | H37: 0.0032 | I37: 0.117
F38: =F37+1 -> 31 | G38: 0.048650963 | H38: 0.0033 | I38: 0.119
B39: Reinsurance Ratios Before Recapture | F39: =F38+1 -> 32 | G39: 0.050597001 | H39: 0.0033 | I39: 0.12
B40: - Reinsurance Premium | C40: 0.7 | D40: as % of Gross Premium | F40: =F39+1 -> 33 | G40: 0.052620881 | H40: 0.0033 | I40: 0.121
B41: - Reinsurance Claims | C41: 0.9 | D41: as % of Gross Claims | F41: =F40+1 -> 34 | G41: 0.054725716 | H41: 0.0035 | I41: 0.122
...

Sheet Projection (Before Recapture)
A1: Key: | B1: To be completed by candidates
B2: Provided data
B4: Projection
B6: After Recapture? (Y/N) | C6: N | T6: Net Profit Margin % | U6: =T10/L10 -> 0.11810688
B8: Year Ending 30 June | C8: Projection Year | D8: Gross Sum Insured In-Force | E8: Gross Premium | F8: Gross Renewal Expense | G8: Gross Renewal Commission | H8: Gross Claims | I8: Reinsurance Premium | J8: Reinsurance Repayment on Recapture | K8: Reinsurance Claims | L8: Present Value of Gross Premium | M8: Present Value of Gross Renewal Expense | N8: Present Value of Gross Renewal Commission | O8: Present Value of Gross Claims | P8: Present Value of Reinsurance Premium | Q8: Present Value of Reinsurance Repayment on Recapture | R8: Present Value of Reinsurance Claims | S8: Net Best Estimate Liability (Net BEL) | T8: Net Present Value of Profit Margins (Net PVPM) | U8: Net Policy Liability (Net PL)
D9: BOY | E9: BOY | F9: BOY | G9: BOY | H9: EOY | I9: BOY | J9: BOY | K9: EOY | L9: EOY | M9: EOY | N9: EOY | O9: EOY | P9: EOY | Q9: EOY | R9: EOY | S9: EOY | T9: EOY | U9: EOY
B10: 2019 | C10: 0 | L10: =NPV('Key Information'!$C$16,E11:E$61)*(1+'Key Information'!$C$16) -> 2.2693329e+09 | M10: =NPV('Key Information'!$C$16,F11:F$61)*(1+'Key Information'!$C$16) -> 1.8303374e+08 | N10: =NPV('Key Information'!$C$16,G11:G$61)*(1+'Key Information'!$C$16) -> 1.1346664e+08 | O10: =NPV('Key Information'!$C$16,H11:H$61) -> 1.0627566e+09 | P10: =NPV('Key Information'!$C$16,I11:I$61)*(1+'Key Information'!$C$16) -> 1.588533e+09 | Q10: =NPV('Key Information'!$C$16,J11:J$61)*(1+'Key Information'!$C$16) -> 0 | R10: =NPV('Key Information'!$C$16,K11:K$61) -> 9.5648094e+08 | S10: =M10+N10+(O10-R10)+Q10-(L10-P10) -> -2.7802382e+08 | T10: =U10-S10 -> 2.6802382e+08 | U10: ='Key Information'!C53 -> -10000000
B11: 2020 | C11: 1 | D11: 55000000000 | E11: =200*10^6 -> 200000000 | F11: ='Key Information'!C25 -> 18000000 | G11: ='Key Information'!$C$30*E11 -> 10000000 | H11: =D11*VLOOKUP($C11,'Key Information'!$F$8:$I$58,3,FALSE) -> 99000000 | I11: =E11*'Key Information'!$C$40 -> 140000000 | J11: =IF(C6="N",0,'Key Information'!$C$47) -> 0 | K11: =H11*'Key Information'!$C$41 -> 89100000 | L11: =NPV('Key Information'!$C$16,E12:E$61)*(1+'Key Information'!$C$16) -> 2.1314128e+09 | M11: =NPV('Key Information'!$C$16,F12:F$61)*(1+'Key Information'!$C$16) -> 1.6998475e+08 | N11: =NPV('Key Information'!$C$16,G12:G$61)*(1+'Key Information'!$C$16) -> 1.0657064e+08 | O11: =NPV('Key Information'!$C$16,H12:H$61) -> 9.956393e+08 | P11: =NPV('Key Information'!$C$16,I12:I$61)*(1+'Key Information'!$C$16) -> 1.491989e+09 | R11: =NPV('Key Information'!$C$16,K12:K$61) -> 8.9607537e+08 | S11: =(M11-R11)+N11+O11+Q11-(L11-P11) -> -2.6330453e+08 | T11: =L11*$U$6 -> 2.5173451e+08 | U11: =S11+T11 -> -11570017
B12: 2021 | C12: 2 | D12: =D11*(1-VLOOKUP($C11,'Key Information'!$F$8:$I$58,4,FALSE)-VLOOKUP($C11,'Key Information'!$F$8:$I$58,3,FALSE))*(1+'Key Information'!$C$21) -> 51062220000 | E12: =(E11*VLOOKUP($C11,'Key Information'!$F$8:$I$58,2,FALSE)+E11)*(1-VLOOKUP($C11,'Key Information'!$F$8:$I$58,4,FALSE)-VLOOKUP($C11,'Key Information'!$F$8:$I$58,3,FALSE))*(1+'Key Information'!$C$21) -> 188466012 | F12: =(F11*'Key Information'!$C$20+F11)*(1-VLOOKUP($C11,'Key Information'!$F$8:$I$58,4,FALSE)-VLOOKUP($C11,'Key Information'!$F$8:$I$58,3,FALSE)) -> 16875108 | G12: ='Key Information'!$C$30*E12 -> 9423300.6 | H12: =D12*VLOOKUP($C12,'Key Information'!$F$8:$I$58,3,FALSE) -> 91911996 | I12: =E12*'Key Information'!$C$40 -> 1.3192621e+08 | K12: =H12*'Key Information'!$C$41 -> 82720796 | L12: =NPV('Key Information'!$C$16,E13:E$61)*(1+'Key Information'!$C$16) -> 2.0012352e+09 | M12: =NPV('Key Information'!$C$16,F13:F$61)*(1+'Key Information'!$C$16) -> 1.5770293e+08 | N12: =NPV('Key Information'!$C$16,G13:G$61)*(1+'Key Information'!$C$16) -> 1.0006176e+08 | O12: =NPV('Key Information'!$C$16,H13:H$61) -> 9.3359648e+08 | P12: =NPV('Key Information'!$C$16,I13:I$61)*(1+'Key Information'!$C$16) -> 1.4008647e+09 | R12: =NPV('Key Information'!$C$16,K13:K$61) -> 8.4023683e+08 | S12: =(M12-R12)+N12+O12+Q12-(L12-P12) -> -2.4924623e+08 | T12: =L12*$U$6 -> 2.3635964e+08 | U12: =S12+T12 -> -12886586
B13: 2022 | C13: 3 | D13: =D12*(1-VLOOKUP($C12,'Key Information'!$F$8:$I$58,4,FALSE)-VLOOKUP($C12,'Key Information'!$F$8:$I$58,3,FALSE))*(1+'Key Information'!$C$21) -> 4.7302202e+10 | E13: =(E12*VLOOKUP($C12,'Key Information'!$F$8:$I$58,2,FALSE)+E12)*(1-VLOOKUP($C12,'Key Information'!$F$8:$I$58,4,FALSE)-VLOOKUP($C12,'Key Information'!$F$8:$I$58,3,FALSE))*(1+'Key Information'!$C$21) -> 1.773117e+08 | F13: =(F12*'Key Information'!$C$20+F12)*(1-VLOOKUP($C12,'Key Information'!$F$8:$I$58,4,FALSE)-VLOOKUP($C12,'Key Information'!$F$8:$I$58,3,FALSE)) -> 15785752 | G13: ='Key Information'!$C$30*E13 -> 8865585.2 | H13: =D13*VLOOKUP($C13,'Key Information'!$F$8:$I$58,3,FALSE) -> 89874184 | I13: =E13*'Key Information'!$C$40 -> 1.2411819e+08 | K13: =H13*'Key Information'!$C$41 -> 80886766 | L13: =NPV('Key Information'!$C$16,E14:E$61)*(1+'Key Information'!$C$16) -> 1.8786412e+09 | M13: =NPV('Key Information'!$C$16,F14:F$61)*(1+'Key Information'!$C$16) -> 1.4617469e+08 | N13: =NPV('Key Information'!$C$16,G14:G$61)*(1+'Key Information'!$C$16) -> 93932062 | O13: =NPV('Key Information'!$C$16,H14:H$61) -> 8.7173019e+08 | P13: =NPV('Key Information'!$C$16,I14:I$61)*(1+'Key Information'!$C$16) -> 1.3150489e+09 | R13: =NPV('Key Information'!$C$16,K14:K$61) -> 7.8455717e+08 | S13: =(M13-R13)+N13+O13+Q13-(L13-P13) -> -2.363126e+08 | T13: =L13*$U$6 -> 2.2188045e+08 | U13: =S13+T13 -> -14432147
B14: 2023 | C14: 4 | D14: =D13*(1-VLOOKUP($C13,'Key Information'!$F$8:$I$58,4,FALSE)-VLOOKUP($C13,'Key Information'!$F$8:$I$58,3,FALSE))*(1+'Key Information'!$C$21) -> 4.3814233e+10 | E14: =(E13*VLOOKUP($C13,'Key Information'!$F$8:$I$58,2,FALSE)+E13)*(1-VLOOKUP($C13,'Key Information'!$F$8:$I$58,4,FALSE)-VLOOKUP($C13,'Key Information'!$F$8:$I$58,3,FALSE))*(1+'Key Information'!$C$21) -> 1.6690168e+08 | F14: =(F13*'Key Information'!$C$20+F13)*(1-VLOOKUP($C13,'Key Information'!$F$8:$I$58,4,FALSE)-VLOOKUP($C13,'Key Information'!$F$8:$I$58,3,FALSE)) -> 14765093 | G14: ='Key Information'!$C$30*E14 -> 8345083.8 | H14: =D14*VLOOKUP($C14,'Key Information'!$F$8:$I$58,3,FALSE) -> 83247042 | I14: =E14*'Key Information'!$C$40 -> 1.1683117e+08 | K14: =H14*'Key Information'!$C$41 -> 74922338 | L14: =NPV('Key Information'!$C$16,E15:E$61)*(1+'Key Information'!$C$16) -> 1.7630918e+09 | M14: =NPV('Key Information'!$C$16,F15:F$61)*(1+'Key Information'!$C$16) -> 1.3535189e+08 | N14: =NPV('Key Information'!$C$16,G15:G$61)*(1+'Key Information'!$C$16) -> 88154588 | O14: =NPV('Key Information'!$C$16,H15:H$61) -> 8.1463505e+08 | P14: =NPV('Key Information'!$C$16,I15:I$61)*(1+'Key Information'!$C$16) -> 1.2341642e+09 | R14: =NPV('Key Information'!$C$16,K15:K$61) -> 7.3317155e+08 | S14: =(M14-R14)+N14+O14+Q14-(L14-P14) -> -2.2395754e+08 | T14: =L14*$U$6 -> 2.0823326e+08 | U14: =S14+T14 -> -15724282
B15: 2024 | C15: 5 | D15: =D14*(1-VLOOKUP($C14,'Key Information'!$F$8:$I$58,4,FALSE)-VLOOKUP($C14,'Key Information'!$F$8:$I$58,3,FALSE))*(1+'Key Information'!$C$21) -> 4.0538768e+10 | E15: =(E14*VLOOKUP($C14,'Key Information'!$F$8:$I$58,2,FALSE)+E14)*(1-VLOOKUP($C14,'Key Information'!$F$8:$I$58,4,FALSE)-VLOOKUP($C14,'Key Information'!$F$8:$I$58,3,FALSE))*(1+'Key Information'!$C$21) -> 1.5703004e+08 | F15: =(F14*'Key Information'!$C$20+F14)*(1-VLOOKUP($C14,'Key Information'!$F$8:$I$58,4,FALSE)-VLOOKUP($C14,'Key Information'!$F$8:$I$58,3,FALSE)) -> 13795218 | G15: ='Key Information'!$C$30*E15 -> 7851501.9 | H15: =D15*VLOOKUP($C15,'Key Information'!$F$8:$I$58,3,FALSE) -> 77023660 | I15: =E15*'Key Information'!$C$40 -> 1.0992103e+08 | K15: =H15*'Key Information'!$C$41 -> 69321294 | L15: =NPV('Key Information'!$C$16,E16:E$61)*(1+'Key Information'!$C$16) -> 1.6542436e+09 | M15: =NPV('Key Information'!$C$16,F16:F$61)*(1+'Key Information'!$C$16) -> 1.2520337e+08 | N15: =NPV('Key Information'!$C$16,G16:G$61)*(1+'Key Information'!$C$16) -> 82712178 | O15: =NPV('Key Information'!$C$16,H16:H$61) -> 7.6205045e+08 | P15: =NPV('Key Information'!$C$16,I16:I$61)*(1+'Key Information'!$C$16) -> 1.1579705e+09 | R15: =NPV('Key Information'!$C$16,K16:K$61) -> 6.858454e+08 | S15: =(M15-R15)+N15+O15+Q15-(L15-P15) -> -2.1215248e+08 | T15: =L15*$U$6 -> 1.9537754e+08 | U15: =S15+T15 -> -16774934
B16: 2025 | C16: 6 | D16: =D15*(1-VLOOKUP($C15,'Key Information'!$F$8:$I$58,4,FALSE)-VLOOKUP($C15,'Key Information'!$F$8:$I$58,3,FALSE))*(1+'Key Information'!$C$21) -> 3.7466821e+10 | E16: =(E15*VLOOKUP($C15,'Key Information'!$F$8:$I$58,2,FALSE)+E15)*(1-VLOOKUP($C15,'Key Information'!$F$8:$I$58,4,FALSE)-VLOOKUP($C15,'Key Information'!$F$8:$I$58,3,FALSE))*(1+'Key Information'!$C$21) -> 1.4767735e+08 | F16: =(F15*'Key Information'!$C$20+F15)*(1-VLOOKUP($C15,'Key Information'!$F$8:$I$58,4,FALSE)-VLOOKUP($C15,'Key Information'!$F$8:$I$58,3,FALSE)) -> 12874843 | G16: ='Key Information'!$C$30*E16 -> 7383867.5 | H16: =D16*VLOOKUP($C16,'Key Information'!$F$8:$I$58,3,FALSE) -> 74933643 | I16: =E16*'Key Information'!$C$40 -> 1.0337414e+08 | K16: =H16*'Key Information'!$C$41 -> 67440279 | L16: =NPV('Key Information'!$C$16,E17:E$61)*(1+'Key Information'!$C$16) -> 1.5517632e+09 | M16: =NPV('Key Information'!$C$16,F17:F$61)*(1+'Key Information'!$C$16) -> 1.1569838e+08 | N16: =NPV('Key Information'!$C$16,G17:G$61)*(1+'Key Information'!$C$16) -> 77588160 | O16: =NPV('Key Information'!$C$16,H17:H$61) -> 7.0997832e+08 | P16: =NPV('Key Information'!$C$16,I17:I$61)*(1+'Key Information'!$C$16) -> 1.0862342e+09 | R16: =NPV('Key Information'!$C$16,K17:K$61) -> 6.3898048e+08 | S16: =(M16-R16)+N16+O16+Q16-(L16-P16) -> -2.0124458e+08 | T16: =L16*$U$6 -> 1.8327391e+08 | U16: =S16+T16 -> -17970678
B17: 2026 | C17: 7 | D17: =D16*(1-VLOOKUP($C16,'Key Information'!$F$8:$I$58,4,FALSE)-VLOOKUP($C16,'Key Information'!$F$8:$I$58,3,FALSE))*(1+'Key Information'!$C$21) -> 3.4623839e+10 | E17: =(E16*VLOOKUP($C16,'Key Information'!$F$8:$I$58,2,FALSE)+E16)*(1-VLOOKUP($C16,'Key Information'!$F$8:$I$58,4,FALSE)-VLOOKUP($C16,'Key Information'!$F$8:$I$58,3,FALSE))*(1+'Key Information'!$C$21) -> 1.3896217e+08 | F17: =(F16*'Key Information'!$C$20+F16)*(1-VLOOKUP($C16,'Key Information'!$F$8:$I$58,4,FALSE)-VLOOKUP($C16,'Key Information'!$F$8:$I$58,3,FALSE)) -> 12014546 | G17: ='Key Information'!$C$30*E17 -> 6948108.5 | H17: =D17*VLOOKUP($C17,'Key Information'!$F$8:$I$58,3,FALSE) -> 69247678 | I17: =E17*'Key Information'!$C$40 -> 97273520 | K17: =H17*'Key Information'!$C$41 -> 62322910 | L17: =NPV('Key Information'!$C$16,E18:E$61)*(1+'Key Information'!$C$16) -> 1.4551851e+09 | M17: =NPV('Key Information'!$C$16,F18:F$61)*(1+'Key Information'!$C$16) -> 1.0679435e+08 | N17: =NPV('Key Information'!$C$16,G18:G$61)*(1+'Key Information'!$C$16) -> 72759253 | O17: =NPV('Key Information'!$C$16,H18:H$61) -> 6.6202999e+08 | P17: =NPV('Key Information'!$C$16,I18:I$61)*(1+'Key Information'!$C$16) -> 1.0186295e+09 | R17: =NPV('Key Information'!$C$16,K18:K$61) -> 5.9582699e+08 | S17: =(M17-R17)+N17+O17+Q17-(L17-P17) -> -1.9079891e+08 | T17: =L17*$U$6 -> 1.7186736e+08 | U17: =S17+T17 -> -18931549
B18: 2027 | C18: 8 | D18: =D17*(1-VLOOKUP($C17,'Key Information'!$F$8:$I$58,4,FALSE)-VLOOKUP($C17,'Key Information'!$F$8:$I$58,3,FALSE))*(1+'Key Information'!$C$21) -> 3.1961266e+10 | E18: =(E17*VLOOKUP($C17,'Key Information'!$F$8:$I$58,2,FALSE)+E17)*(1-VLOOKUP($C17,'Key Information'!$F$8:$I$58,4,FALSE)-VLOOKUP($C17,'Key Information'!$F$8:$I$58,3,FALSE))*(1+'Key Information'!$C$21) -> 1.3071063e+08 | F18: =(F17*'Key Information'!$C$20+F17)*(1-VLOOKUP($C17,'Key Information'!$F$8:$I$58,4,FALSE)-VLOOKUP($C17,'Key Information'!$F$8:$I$58,3,FALSE)) -> 11199359 | G18: ='Key Information'!$C$30*E18 -> 6535531.5 | H18: =D18*VLOOKUP($C18,'Key Information'!$F$8:$I$58,3,FALSE) -> 67118658 | I18: =E18*'Key Information'!$C$40 -> 91497441 | K18: =H18*'Key Information'!$C$41 -> 60406792 | L18: =NPV('Key Information'!$C$16,E19:E$61)*(1+'Key Information'!$C$16) -> 1.3642087e+09 | M18: =NPV('Key Information'!$C$16,F19:F$61)*(1+'Key Information'!$C$16) -> 98462845 | N18: =NPV('Key Information'!$C$16,G19:G$61)*(1+'Key Information'!$C$16) -> 68210433 | O18: =NPV('Key Information'!$C$16,H19:H$61) -> 6.1477223e+08 | P18: =NPV('Key Information'!$C$16,I19:I$61)*(1+'Key Information'!$C$16) -> 9.5494606e+08 | R18: =NPV('Key Information'!$C$16,K19:K$61) -> 5.5329501e+08 | S18: =(M18-R18)+N18+O18+Q18-(L18-P18) -> -1.811121e+08 | T18: =L18*$U$6 -> 1.6112242e+08 | U18: =S18+T18 -> -19989673
B19: 2028 | C19: 9 | D19: =D18*(1-VLOOKUP($C18,'Key Information'!$F$8:$I$58,4,FALSE)-VLOOKUP($C18,'Key Information'!$F$8:$I$58,3,FALSE))*(1+'Key Information'!$C$21) -> 2.9467584e+10 | E19: =(E18*VLOOKUP($C18,'Key Information'!$F$8:$I$58,2,FALSE)+E18)*(1-VLOOKUP($C18,'Key Information'!$F$8:$I$58,4,FALSE)-VLOOKUP($C18,'Key Information'!$F$8:$I$58,3,FALSE))*(1+'Key Information'!$C$21) -> 1.2289112e+08 | F19: =(F18*'Key Information'!$C$20+F18)*(1-VLOOKUP($C18,'Key Information'!$F$8:$I$58,4,FALSE)-VLOOKUP($C18,'Key Information'!$F$8:$I$58,3,FALSE)) -> 10426793 | G19: ='Key Information'!$C$30*E19 -> 6144555.8 | H19: =D19*VLOOKUP($C19,'Key Information'!$F$8:$I$58,3,FALSE) -> 61881926 | I19: =E19*'Key Information'!$C$40 -> 86023781 | K19: =H19*'Key Information'!$C$41 -> 55693734 | L19: =NPV('Key Information'!$C$16,E20:E$61)*(1+'Key Information'!$C$16) -> 1.2785571e+09 | M19: =NPV('Key Information'!$C$16,F20:F$61)*(1+'Key Information'!$C$16) -> 90677133 | N19: =NPV('Key Information'!$C$16,G20:G$61)*(1+'Key Information'!$C$16) -> 63927854 | O19: =NPV('Key Information'!$C$16,H20:H$61) -> 5.7133347e+08 | P19: =NPV('Key Information'!$C$16,I20:I$61)*(1+'Key Information'!$C$16) -> 8.9498995e+08 | R19: =NPV('Key Information'!$C$16,K20:K$61) -> 5.1420012e+08 | S19: =(M19-R19)+N19+O19+Q19-(L19-P19) -> -1.7182879e+08 | T19: =L19*$U$6 -> 1.5100638e+08 | U19: =S19+T19 -> -20822405
B20: 2029 | C20: 10 | D20: =D19*(1-VLOOKUP($C19,'Key Information'!$F$8:$I$58,4,FALSE)-VLOOKUP($C19,'Key Information'!$F$8:$I$58,3,FALSE))*(1+'Key Information'!$C$21) -> 2.7138407e+10 | E20: =(E19*VLOOKUP($C19,'Key Information'!$F$8:$I$58,2,FALSE)+E19)*(1-VLOOKUP($C19,'Key Information'!$F$8:$I$58,4,FALSE)-VLOOKUP($C19,'Key Information'!$F$8:$I$58,3,FALSE))*(1+'Key Information'!$C$21) -> 1.1550093e+08 | F20: =(F19*'Key Information'!$C$20+F19)*(1-VLOOKUP($C19,'Key Information'!$F$8:$I$58,4,FALSE)-VLOOKUP($C19,'Key Information'!$F$8:$I$58,3,FALSE)) -> 9696782.3 | G20: ='Key Information'!$C$30*E20 -> 5775046.3 | H20: =D20*VLOOKUP($C20,'Key Information'!$F$8:$I$58,3,FALSE) -> 56990655 | I20: =E20*'Key Information'!$C$40 -> 80850648 | K20: =H20*'Key Information'!$C$41 -> 51291589 | L20: =NPV('Key Information'!$C$16,E21:E$61)*(1+'Key Information'!$C$16) -> 1.1979478e+09 | M20: =NPV('Key Information'!$C$16,F21:F$61)*(1+'Key Information'!$C$16) -> 83409762 | N20: =NPV('Key Information'!$C$16,G21:G$61)*(1+'Key Information'!$C$16) -> 59897392 | O20: =NPV('Key Information'!$C$16,H21:H$61) -> 5.3148282e+08 | P20: =NPV('Key Information'!$C$16,I21:I$61)*(1+'Key Information'!$C$16) -> 8.3856348e+08 | R20: =NPV('Key Information'!$C$16,K21:K$61) -> 4.7833454e+08 | S20: =(M20-R20)+N20+O20+Q20-(L20-P20) -> -1.6292891e+08 | T20: =L20*$U$6 -> 1.4148588e+08 | U20: =S20+T20 -> -21443037
B21: 2030 | C21: 11 | D21: =D20*(1-VLOOKUP($C20,'Key Information'!$F$8:$I$58,4,FALSE)-VLOOKUP($C20,'Key Information'!$F$8:$I$58,3,FALSE))*(1+'Key Information'!$C$21) -> 2.4965652e+10 | E21: =(E20*VLOOKUP($C20,'Key Information'!$F$8:$I$58,2,FALSE)+E20)*(1-VLOOKUP($C20,'Key Information'!$F$8:$I$58,4,FALSE)-VLOOKUP($C20,'Key Information'!$F$8:$I$58,3,FALSE))*(1+'Key Information'!$C$21) -> 1.0852217e+08 | F21: =(F20*'Key Information'!$C$20+F20)*(1-VLOOKUP($C20,'Key Information'!$F$8:$I$58,4,FALSE)-VLOOKUP($C20,'Key Information'!$F$8:$I$58,3,FALSE)) -> 9007893.8 | G21: ='Key Information'!$C$30*E21 -> 5426108.6 | H21: =D21*VLOOKUP($C21,'Key Information'!$F$8:$I$58,3,FALSE) -> 54924434 | I21: =E21*'Key Information'!$C$40 -> 75965521 | K21: =H21*'Key Information'!$C$41 -> 49431991 | L21: =NPV('Key Information'!$C$16,E22:E$61)*(1+'Key Information'!$C$16) -> 1.1221084e+09 | M21: =NPV('Key Information'!$C$16,F22:F$61)*(1+'Key Information'!$C$16) -> 76633924 | N21: =NPV('Key Information'!$C$16,G22:G$61)*(1+'Key Information'!$C$16) -> 56105422 | O21: =NPV('Key Information'!$C$16,H22:H$61) -> 4.9250287e+08 | P21: =NPV('Key Information'!$C$16,I22:I$61)*(1+'Key Information'!$C$16) -> 7.854759e+08 | R21: =NPV('Key Information'!$C$16,K22:K$61) -> 4.4325258e+08 | S21: =(M21-R21)+N21+O21+Q21-(L21-P21) -> -1.546429e+08 | T21: =L21*$U$6 -> 1.3252872e+08 | U21: =S21+T21 -> -22114174
B22: 2031 | C22: 12 | D22: =D21*(1-VLOOKUP($C21,'Key Information'!$F$8:$I$58,4,FALSE)-VLOOKUP($C21,'Key Information'!$F$8:$I$58,3,FALSE))*(1+'Key Information'!$C$21) -> 2.293884e+10 | E22: =(E21*VLOOKUP($C21,'Key Information'!$F$8:$I$58,2,FALSE)+E21)*(1-VLOOKUP($C21,'Key Information'!$F$8:$I$58,4,FALSE)-VLOOKUP($C21,'Key Information'!$F$8:$I$58,3,FALSE))*(1+'Key Information'!$C$21) -> 1.0192588e+08 | F22: =(F21*'Key Information'!$C$20+F21)*(1-VLOOKUP($C21,'Key Information'!$F$8:$I$58,4,FALSE)-VLOOKUP($C21,'Key Information'!$F$8:$I$58,3,FALSE)) -> 8357740.1 | G22: ='Key Information'!$C$30*E22 -> 5096293.9 | H22: =D22*VLOOKUP($C22,'Key Information'!$F$8:$I$58,3,FALSE) -> 50465449 | I22: =E22*'Key Information'!$C$40 -> 71348115 | K22: =H22*'Key Information'!$C$41 -> 45418904 | L22: =NPV('Key Information'!$C$16,E23:E$61)*(1+'Key Information'!$C$16) -> 1.050788e+09 | M22: =NPV('Key Information'!$C$16,F23:F$61)*(1+'Key Information'!$C$16) -> 70324469 | N22: =NPV('Key Information'!$C$16,G23:G$61)*(1+'Key Information'!$C$16) -> 52539401 | O22: =NPV('Key Information'!$C$16,H23:H$61) -> 4.5681251e+08 | P22: =NPV('Key Information'!$C$16,I23:I$61)*(1+'Key Information'!$C$16) -> 7.3555162e+08 | R22: =NPV('Key Information'!$C$16,K23:K$61) -> 4.1113126e+08 | S22: =(M22-R22)+N22+O22+Q22-(L22-P22) -> -1.4669129e+08 | T22: =L22*$U$6 -> 1.2410529e+08 | U22: =S22+T22 -> -22585995
B23: 2032 | C23: 13 | D23: =D22*(1-VLOOKUP($C22,'Key Information'!$F$8:$I$58,4,FALSE)-VLOOKUP($C22,'Key Information'!$F$8:$I$58,3,FALSE))*(1+'Key Information'!$C$21) -> 2.1053176e+10 | E23: =(E22*VLOOKUP($C22,'Key Information'!$F$8:$I$58,2,FALSE)+E22)*(1-VLOOKUP($C22,'Key Information'!$F$8:$I$58,4,FALSE)-VLOOKUP($C22,'Key Information'!$F$8:$I$58,3,FALSE))*(1+'Key Information'!$C$21) -> 95707337 | F23: =(F22*'Key Information'!$C$20+F22)*(1-VLOOKUP($C22,'Key Information'!$F$8:$I$58,4,FALSE)-VLOOKUP($C22,'Key Information'!$F$8:$I$58,3,FALSE)) -> 7745903.3 | G23: ='Key Information'!$C$30*E23 -> 4785366.8 | H23: =D23*VLOOKUP($C23,'Key Information'!$F$8:$I$58,3,FALSE) -> 48422305 | I23: =E23*'Key Information'!$C$40 -> 66995136 | K23: =H23*'Key Information'!$C$41 -> 43580074 | L23: =NPV('Key Information'!$C$16,E24:E$61)*(1+'Key Information'!$C$16) -> 9.8373311e+08 | M23: =NPV('Key Information'!$C$16,F24:F$61)*(1+'Key Information'!$C$16) -> 64455923 | N23: =NPV('Key Information'!$C$16,G24:G$61)*(1+'Key Information'!$C$16) -> 49186656 | O23: =NPV('Key Information'!$C$16,H24:H$61) -> 4.2209458e+08 | P23: =NPV('Key Information'!$C$16,I24:I$61)*(1+'Key Information'!$C$16) -> 6.8861318e+08 | R23: =NPV('Key Information'!$C$16,K24:K$61) -> 3.7988512e+08 | S23: =(M23-R23)+N23+O23+Q23-(L23-P23) -> -1.392679e+08 | T23: =L23*$U$6 -> 1.1618565e+08 | U23: =S23+T23 -> -23082252
... B60: 2069 | C60: 50 | D60: =D59*(1-VLOOKUP($C59,'Key Information'!$F$8:$I$58,4,FALSE)-VLOOKUP($C59,'Key Information'!$F$8:$I$58,3,FALSE))*(1+'Key Information'!$C$21) -> 3.4594012e+08 | E60: =(E59*VLOOKUP($C59,'Key Information'!$F$8:$I$58,2,FALSE)+E59)*(1-VLOOKUP($C59,'Key Information'!$F$8:$I$58,4,FALSE)-VLOOKUP($C59,'Key Information'!$F$8:$I$58,3,FALSE))*(1+'Key Information'!$C$21) -> 10556225 | F60: =(F59*'Key Information'!$C$20+F59)*(1-VLOOKUP($C59,'Key Information'!$F$8:$I$58,4,FALSE)-VLOOKUP($C59,'Key Information'!$F$8:$I$58,3,FALSE)) -> 182610.75 | G60: ='Key Information'!$C$30*E60 -> 527811.23 | H60: =D60*VLOOKUP($C60,'Key Information'!$F$8:$I$58,3,FALSE) -> 1625918.6 | I60: =E60*'Key Information'!$C$40 -> 7389357.2 | K60: =H60*'Key Information'!$C$41 -> 1463326.7 | L60: =NPV('Key Information'!$C$16,E61:E$61)*(1+'Key Information'!$C$16) -> 10117657 | M60: =NPV('Key Information'!$C$16,F61:F$61)*(1+'Key Information'!$C$16) -> 160308.32 | N60: =NPV('Key Information'!$C$16,G61:G$61)*(1+'Key Information'!$C$16) -> 505882.87 | O60: =NPV('Key Information'!$C$16,H61:H$61) -> 1372316.3 | P60: =NPV('Key Information'!$C$16,I61:I$61)*(1+'Key Information'!$C$16) -> 7082360.2 | R60: =NPV('Key Information'!$C$16,K61:K$61) -> 1235084.7 | S60: =(M60-R60)+N60+O60+Q60-(L60-P60) -> -2231874.4 | T60: =L60*$U$6 -> 1194964.9 | U60: =S60+T60 -> -1036909.5
B61: 2070 | C61: 51 | D61: =D60*(1-VLOOKUP($C60,'Key Information'!$F$8:$I$58,4,FALSE)-VLOOKUP($C60,'Key Information'!$F$8:$I$58,3,FALSE))*(1+'Key Information'!$C$21) -> 3.0074166e+08 | E61: =(E60*VLOOKUP($C60,'Key Information'!$F$8:$I$58,2,FALSE)+E60)*(1-VLOOKUP($C60,'Key Information'!$F$8:$I$58,4,FALSE)-VLOOKUP($C60,'Key Information'!$F$8:$I$58,3,FALSE))*(1+'Key Information'!$C$21) -> 10117657 | F61: =(F60*'Key Information'!$C$20+F60)*(1-VLOOKUP($C60,'Key Information'!$F$8:$I$58,4,FALSE)-VLOOKUP($C60,'Key Information'!$F$8:$I$58,3,FALSE)) -> 160308.32 | G61: ='Key Information'!$C$30*E61 -> 505882.87 | H61: =D61*VLOOKUP($C61,'Key Information'!$F$8:$I$58,3,FALSE) -> 1413485.8 | I61: =E61*'Key Information'!$C$40 -> 7082360.2 | K61: =H61*'Key Information'!$C$41 -> 1272137.2 | L61: 0 | M61: 0 | N61: 0 | O61: 0 | P61: 0 | R61: 0 | S61: =(M61-R61)+N61+O61+Q61-(L61-P61) -> 0 | T61: =L61*$U$6 -> 0 | U61: =S61+T61 -> 0

Sheet Projection (After Recapture)
A1: Key: | B1: To be completed by candidates
B2: Provided data
B4: Projection
B6: After Recapture? (Y/N) | C6: Y | T6: Net Profit Margin % | U6: =T10/L10 -> 0.13579359
B8: Year Ending 30 June | C8: Projection Year | D8: Gross Sum Insured In-Force | E8: Gross Premium | F8: Gross Renewal Expense | G8: Gross Renewal Commission | H8: Gross Claims | I8: Reinsurance Premium | J8: Reinsurance Repayment on Recapture | K8: Reinsurance Claims | L8: Present Value of Gross Premium | M8: Present Value of Gross Renewal Expense | N8: Present Value of Gross Renewal Commission | O8: Present Value of Gross Claims | P8: Present Value of Reinsurance Premium | Q8: Present Value of Reinsurance Repayment on Recapture | R8: Present Value of Reinsurance Claims | S8: Net Best Estimate Liability (Net BEL) | T8: Net Present Value of Profit Margins (Net PVPM) | U8: Net Policy Liability (Net PL)
D9: BOY | E9: BOY | F9: BOY | G9: BOY | H9: EOY | I9: BOY | J9: BOY | K9: EOY | L9: EOY | M9: EOY | N9: EOY | O9: EOY | P9: EOY | Q9: EOY | R9: EOY | S9: EOY | T9: EOY | U9: EOY
B10: 2019 | C10: 0 | L10: =NPV('Key Information'!$C$16,E11:E$61)*(1+'Key Information'!$C$16) -> 2.2693329e+09 | M10: =NPV('Key Information'!$C$16,F11:F$61)*(1+'Key Information'!$C$16) -> 1.8303374e+08 | N10: =NPV('Key Information'!$C$16,G11:G$61)*(1+'Key Information'!$C$16) -> 1.1346664e+08 | O10: =NPV('Key Information'!$C$16,H11:H$61) -> 1.0627566e+09 | P10: =NPV('Key Information'!$C$16,I11:I$61)*(1+'Key Information'!$C$16) -> 7.4887984e+08 | Q10: =NPV('Key Information'!$C$16,J11:J$61)*(1+'Key Information'!$C$16) -> 215000000 | R10: =NPV('Key Information'!$C$16,K11:K$61) -> 3.7196481e+08 | S10: =M10+N10+(O10-R10)+Q10-(L10-P10) -> -3.1816085e+08 | T10: =U10-S10 -> 3.0816085e+08 | U10: ='Key Information'!C53 -> -10000000
B11: 2020 | C11: 1 | D11: 55000000000 | E11: =200*10^6 -> 200000000 | F11: ='Key Information'!C25 -> 18000000 | G11: ='Key Information'!$C$30*E11 -> 10000000 | H11: =D11*VLOOKUP($C11,'Key Information'!$F$8:$I$58,3,FALSE) -> 99000000 | I11: =E11*'Key Information'!$C$44 -> 66000000 | J11: =IF(C6="N",0,'Key Information'!$C$47) -> 215000000 | K11: =H11*'Key Information'!$C$45 -> 34650000 | L11: =NPV('Key Information'!$C$16,E12:E$61)*(1+'Key Information'!$C$16) -> 2.1314128e+09 | M11: =NPV('Key Information'!$C$16,F12:F$61)*(1+'Key Information'!$C$16) -> 1.6998475e+08 | N11: =NPV('Key Information'!$C$16,G12:G$61)*(1+'Key Information'!$C$16) -> 1.0657064e+08 | O11: =NPV('Key Information'!$C$16,H12:H$61) -> 9.956393e+08 | P11: =NPV('Key Information'!$C$16,I12:I$61)*(1+'Key Information'!$C$16) -> 7.0336624e+08 | R11: =NPV('Key Information'!$C$16,K12:K$61) -> 3.4847375e+08 | S11: =(M11-R11)+N11+O11+Q11-(L11-P11) -> -5.0432567e+08 | T11: =L11*$U$6 -> 2.8943219e+08 | U11: =S11+T11 -> -2.1489348e+08
B12: 2021 | C12: 2 | D12: =D11*(1-VLOOKUP($C11,'Key Information'!$F$8:$I$58,4,FALSE)-VLOOKUP($C11,'Key Information'!$F$8:$I$58,3,FALSE))*(1+'Key Information'!$C$21) -> 51062220000 | E12: =(E11*VLOOKUP($C11,'Key Information'!$F$8:$I$58,2,FALSE)+E11)*(1-VLOOKUP($C11,'Key Information'!$F$8:$I$58,4,FALSE)-VLOOKUP($C11,'Key Information'!$F$8:$I$58,3,FALSE))*(1+'Key Information'!$C$21) -> 188466012 | F12: =(F11*'Key Information'!$C$20+F11)*(1-VLOOKUP($C11,'Key Information'!$F$8:$I$58,4,FALSE)-VLOOKUP($C11,'Key Information'!$F$8:$I$58,3,FALSE)) -> 16875108 | G12: ='Key Information'!$C$30*E12 -> 9423300.6 | H12: =D12*VLOOKUP($C12,'Key Information'!$F$8:$I$58,3,FALSE) -> 91911996 | I12: =E12*'Key Information'!$C$44 -> 62193784 | K12: =H12*'Key Information'!$C$45 -> 32169199 | L12: =NPV('Key Information'!$C$16,E13:E$61)*(1+'Key Information'!$C$16) -> 2.0012352e+09 | M12: =NPV('Key Information'!$C$16,F13:F$61)*(1+'Key Information'!$C$16) -> 1.5770293e+08 | N12: =NPV('Key Information'!$C$16,G13:G$61)*(1+'Key Information'!$C$16) -> 1.0006176e+08 | O12: =NPV('Key Information'!$C$16,H13:H$61) -> 9.3359648e+08 | P12: =NPV('Key Information'!$C$16,I13:I$61)*(1+'Key Information'!$C$16) -> 6.6040763e+08 | R12: =NPV('Key Information'!$C$16,K13:K$61) -> 3.2675877e+08 | S12: =(M12-R12)+N12+O12+Q12-(L12-P12) -> -4.762252e+08 | T12: =L12*$U$6 -> 2.7175491e+08 | U12: =S12+T12 -> -2.044703e+08
B13: 2022 | C13: 3 | D13: =D12*(1-VLOOKUP($C12,'Key Information'!$F$8:$I$58,4,FALSE)-VLOOKUP($C12,'Key Information'!$F$8:$I$58,3,FALSE))*(1+'Key Information'!$C$21) -> 4.7302202e+10 | E13: =(E12*VLOOKUP($C12,'Key Information'!$F$8:$I$58,2,FALSE)+E12)*(1-VLOOKUP($C12,'Key Information'!$F$8:$I$58,4,FALSE)-VLOOKUP($C12,'Key Information'!$F$8:$I$58,3,FALSE))*(1+'Key Information'!$C$21) -> 1.773117e+08 | F13: =(F12*'Key Information'!$C$20+F12)*(1-VLOOKUP($C12,'Key Information'!$F$8:$I$58,4,FALSE)-VLOOKUP($C12,'Key Information'!$F$8:$I$58,3,FALSE)) -> 15785752 | G13: ='Key Information'!$C$30*E13 -> 8865585.2 | H13: =D13*VLOOKUP($C13,'Key Information'!$F$8:$I$58,3,FALSE) -> 89874184 | I13: =E13*'Key Information'!$C$44 -> 58512862 | K13: =H13*'Key Information'!$C$45 -> 31455965 | L13: =NPV('Key Information'!$C$16,E14:E$61)*(1+'Key Information'!$C$16) -> 1.8786412e+09 | M13: =NPV('Key Information'!$C$16,F14:F$61)*(1+'Key Information'!$C$16) -> 1.4617469e+08 | N13: =NPV('Key Information'!$C$16,G14:G$61)*(1+'Key Information'!$C$16) -> 93932062 | O13: =NPV('Key Information'!$C$16,H14:H$61) -> 8.7173019e+08 | P13: =NPV('Key Information'!$C$16,I14:I$61)*(1+'Key Information'!$C$16) -> 6.1995161e+08 | R13: =NPV('Key Information'!$C$16,K14:K$61) -> 3.0510557e+08 | S13: =(M13-R13)+N13+O13+Q13-(L13-P13) -> -4.5195825e+08 | T13: =L13*$U$6 -> 2.5510743e+08 | U13: =S13+T13 -> -1.9685082e+08
B14: 2023 | C14: 4 | D14: =D13*(1-VLOOKUP($C13,'Key Information'!$F$8:$I$58,4,FALSE)-VLOOKUP($C13,'Key Information'!$F$8:$I$58,3,FALSE))*(1+'Key Information'!$C$21) -> 4.3814233e+10 | E14: =(E13*VLOOKUP($C13,'Key Information'!$F$8:$I$58,2,FALSE)+E13)*(1-VLOOKUP($C13,'Key Information'!$F$8:$I$58,4,FALSE)-VLOOKUP($C13,'Key Information'!$F$8:$I$58,3,FALSE))*(1+'Key Information'!$C$21) -> 1.6690168e+08 | F14: =(F13*'Key Information'!$C$20+F13)*(1-VLOOKUP($C13,'Key Information'!$F$8:$I$58,4,FALSE)-VLOOKUP($C13,'Key Information'!$F$8:$I$58,3,FALSE)) -> 14765093 | G14: ='Key Information'!$C$30*E14 -> 8345083.8 | H14: =D14*VLOOKUP($C14,'Key Information'!$F$8:$I$58,3,FALSE) -> 83247042 | I14: =E14*'Key Information'!$C$44 -> 55077553 | K14: =H14*'Key Information'!$C$45 -> 29136465 | L14: =NPV('Key Information'!$C$16,E15:E$61)*(1+'Key Information'!$C$16) -> 1.7630918e+09 | M14: =NPV('Key Information'!$C$16,F15:F$61)*(1+'Key Information'!$C$16) -> 1.3535189e+08 | N14: =NPV('Key Information'!$C$16,G15:G$61)*(1+'Key Information'!$C$16) -> 88154588 | O14: =NPV('Key Information'!$C$16,H15:H$61) -> 8.1463505e+08 | P14: =NPV('Key Information'!$C$16,I15:I$61)*(1+'Key Information'!$C$16) -> 5.8182028e+08 | R14: =NPV('Key Information'!$C$16,K15:K$61) -> 2.8512227e+08 | S14: =(M14-R14)+N14+O14+Q14-(L14-P14) -> -4.2825221e+08 | T14: =L14*$U$6 -> 2.3941655e+08 | U14: =S14+T14 -> -1.8883566e+08
B15: 2024 | C15: 5 | D15: =D14*(1-VLOOKUP($C14,'Key Information'!$F$8:$I$58,4,FALSE)-VLOOKUP($C14,'Key Information'!$F$8:$I$58,3,FALSE))*(1+'Key Information'!$C$21) -> 4.0538768e+10 | E15: =(E14*VLOOKUP($C14,'Key Information'!$F$8:$I$58,2,FALSE)+E14)*(1-VLOOKUP($C14,'Key Information'!$F$8:$I$58,4,FALSE)-VLOOKUP($C14,'Key Information'!$F$8:$I$58,3,FALSE))*(1+'Key Information'!$C$21) -> 1.5703004e+08 | F15: =(F14*'Key Information'!$C$20+F14)*(1-VLOOKUP($C14,'Key Information'!$F$8:$I$58,4,FALSE)-VLOOKUP($C14,'Key Information'!$F$8:$I$58,3,FALSE)) -> 13795218 | G15: ='Key Information'!$C$30*E15 -> 7851501.9 | H15: =D15*VLOOKUP($C15,'Key Information'!$F$8:$I$58,3,FALSE) -> 77023660 | I15: =E15*'Key Information'!$C$44 -> 51819912 | K15: =H15*'Key Information'!$C$45 -> 26958281 | L15: =NPV('Key Information'!$C$16,E16:E$61)*(1+'Key Information'!$C$16) -> 1.6542436e+09 | M15: =NPV('Key Information'!$C$16,F16:F$61)*(1+'Key Information'!$C$16) -> 1.2520337e+08 | N15: =NPV('Key Information'!$C$16,G16:G$61)*(1+'Key Information'!$C$16) -> 82712178 | O15: =NPV('Key Information'!$C$16,H16:H$61) -> 7.6205045e+08 | P15: =NPV('Key Information'!$C$16,I16:I$61)*(1+'Key Information'!$C$16) -> 5.4590038e+08 | R15: =NPV('Key Information'!$C$16,K16:K$61) -> 2.6671766e+08 | S15: =(M15-R15)+N15+O15+Q15-(L15-P15) -> -4.0509485e+08 | T15: =L15*$U$6 -> 2.2463566e+08 | U15: =S15+T15 -> -1.8045918e+08
B16: 2025 | C16: 6 | D16: =D15*(1-VLOOKUP($C15,'Key Information'!$F$8:$I$58,4,FALSE)-VLOOKUP($C15,'Key Information'!$F$8:$I$58,3,FALSE))*(1+'Key Information'!$C$21) -> 3.7466821e+10 | E16: =(E15*VLOOKUP($C15,'Key Information'!$F$8:$I$58,2,FALSE)+E15)*(1-VLOOKUP($C15,'Key Information'!$F$8:$I$58,4,FALSE)-VLOOKUP($C15,'Key Information'!$F$8:$I$58,3,FALSE))*(1+'Key Information'!$C$21) -> 1.4767735e+08 | F16: =(F15*'Key Information'!$C$20+F15)*(1-VLOOKUP($C15,'Key Information'!$F$8:$I$58,4,FALSE)-VLOOKUP($C15,'Key Information'!$F$8:$I$58,3,FALSE)) -> 12874843 | G16: ='Key Information'!$C$30*E16 -> 7383867.5 | H16: =D16*VLOOKUP($C16,'Key Information'!$F$8:$I$58,3,FALSE) -> 74933643 | I16: =E16*'Key Information'!$C$44 -> 48733525 | K16: =H16*'Key Information'!$C$45 -> 26226775 | L16: =NPV('Key Information'!$C$16,E17:E$61)*(1+'Key Information'!$C$16) -> 1.5517632e+09 | M16: =NPV('Key Information'!$C$16,F17:F$61)*(1+'Key Information'!$C$16) -> 1.1569838e+08 | N16: =NPV('Key Information'!$C$16,G17:G$61)*(1+'Key Information'!$C$16) -> 77588160 | O16: =NPV('Key Information'!$C$16,H17:H$61) -> 7.0997832e+08 | P16: =NPV('Key Information'!$C$16,I17:I$61)*(1+'Key Information'!$C$16) -> 5.1208186e+08 | R16: =NPV('Key Information'!$C$16,K17:K$61) -> 2.4849241e+08 | S16: =(M16-R16)+N16+O16+Q16-(L16-P16) -> -3.8490889e+08 | T16: =L16*$U$6 -> 2.1071949e+08 | U16: =S16+T16 -> -1.7418941e+08
B17: 2026 | C17: 7 | D17: =D16*(1-VLOOKUP($C16,'Key Information'!$F$8:$I$58,4,FALSE)-VLOOKUP($C16,'Key Information'!$F$8:$I$58,3,FALSE))*(1+'Key Information'!$C$21) -> 3.4623839e+10 | E17: =(E16*VLOOKUP($C16,'Key Information'!$F$8:$I$58,2,FALSE)+E16)*(1-VLOOKUP($C16,'Key Information'!$F$8:$I$58,4,FALSE)-VLOOKUP($C16,'Key Information'!$F$8:$I$58,3,FALSE))*(1+'Key Information'!$C$21) -> 1.3896217e+08 | F17: =(F16*'Key Information'!$C$20+F16)*(1-VLOOKUP($C16,'Key Information'!$F$8:$I$58,4,FALSE)-VLOOKUP($C16,'Key Information'!$F$8:$I$58,3,FALSE)) -> 12014546 | G17: ='Key Information'!$C$30*E17 -> 6948108.5 | H17: =D17*VLOOKUP($C17,'Key Information'!$F$8:$I$58,3,FALSE) -> 69247678 | I17: =E17*'Key Information'!$C$44 -> 45857516 | K17: =H17*'Key Information'!$C$45 -> 24236687 | L17: =NPV('Key Information'!$C$16,E18:E$61)*(1+'Key Information'!$C$16) -> 1.4551851e+09 | M17: =NPV('Key Information'!$C$16,F18:F$61)*(1+'Key Information'!$C$16) -> 1.0679435e+08 | N17: =NPV('Key Information'!$C$16,G18:G$61)*(1+'Key Information'!$C$16) -> 72759253 | O17: =NPV('Key Information'!$C$16,H18:H$61) -> 6.6202999e+08 | P17: =NPV('Key Information'!$C$16,I18:I$61)*(1+'Key Information'!$C$16) -> 4.8021107e+08 | R17: =NPV('Key Information'!$C$16,K18:K$61) -> 2.317105e+08 | S17: =(M17-R17)+N17+O17+Q17-(L17-P17) -> -3.6510089e+08 | T17: =L17*$U$6 -> 1.976048e+08 | U17: =S17+T17 -> -1.674961e+08
B18: 2027 | C18: 8 | D18: =D17*(1-VLOOKUP($C17,'Key Information'!$F$8:$I$58,4,FALSE)-VLOOKUP($C17,'Key Information'!$F$8:$I$58,3,FALSE))*(1+'Key Information'!$C$21) -> 3.1961266e+10 | E18: =(E17*VLOOKUP($C17,'Key Information'!$F$8:$I$58,2,FALSE)+E17)*(1-VLOOKUP($C17,'Key Information'!$F$8:$I$58,4,FALSE)-VLOOKUP($C17,'Key Information'!$F$8:$I$58,3,FALSE))*(1+'Key Information'!$C$21) -> 1.3071063e+08 | F18: =(F17*'Key Information'!$C$20+F17)*(1-VLOOKUP($C17,'Key Information'!$F$8:$I$58,4,FALSE)-VLOOKUP($C17,'Key Information'!$F$8:$I$58,3,FALSE)) -> 11199359 | G18: ='Key Information'!$C$30*E18 -> 6535531.5 | H18: =D18*VLOOKUP($C18,'Key Information'!$F$8:$I$58,3,FALSE) -> 67118658 | I18: =E18*'Key Information'!$C$44 -> 43134508 | K18: =H18*'Key Information'!$C$45 -> 23491530 | L18: =NPV('Key Information'!$C$16,E19:E$61)*(1+'Key Information'!$C$16) -> 1.3642087e+09 | M18: =NPV('Key Information'!$C$16,F19:F$61)*(1+'Key Information'!$C$16) -> 98462845 | N18: =NPV('Key Information'!$C$16,G19:G$61)*(1+'Key Information'!$C$16) -> 68210433 | O18: =NPV('Key Information'!$C$16,H19:H$61) -> 6.1477223e+08 | P18: =NPV('Key Information'!$C$16,I19:I$61)*(1+'Key Information'!$C$16) -> 4.5018886e+08 | R18: =NPV('Key Information'!$C$16,K19:K$61) -> 2.1517028e+08 | S18: =(M18-R18)+N18+O18+Q18-(L18-P18) -> -3.4774458e+08 | T18: =L18*$U$6 -> 1.8525079e+08 | U18: =S18+T18 -> -1.6249379e+08
B19: 2028 | C19: 9 | D19: =D18*(1-VLOOKUP($C18,'Key Information'!$F$8:$I$58,4,FALSE)-VLOOKUP($C18,'Key Information'!$F$8:$I$58,3,FALSE))*(1+'Key Information'!$C$21) -> 2.9467584e+10 | E19: =(E18*VLOOKUP($C18,'Key Information'!$F$8:$I$58,2,FALSE)+E18)*(1-VLOOKUP($C18,'Key Information'!$F$8:$I$58,4,FALSE)-VLOOKUP($C18,'Key Information'!$F$8:$I$58,3,FALSE))*(1+'Key Information'!$C$21) -> 1.2289112e+08 | F19: =(F18*'Key Information'!$C$20+F18)*(1-VLOOKUP($C18,'Key Information'!$F$8:$I$58,4,FALSE)-VLOOKUP($C18,'Key Information'!$F$8:$I$58,3,FALSE)) -> 10426793 | G19: ='Key Information'!$C$30*E19 -> 6144555.8 | H19: =D19*VLOOKUP($C19,'Key Information'!$F$8:$I$58,3,FALSE) -> 61881926 | I19: =E19*'Key Information'!$C$44 -> 40554068 | K19: =H19*'Key Information'!$C$45 -> 21658674 | L19: =NPV('Key Information'!$C$16,E20:E$61)*(1+'Key Information'!$C$16) -> 1.2785571e+09 | M19: =NPV('Key Information'!$C$16,F20:F$61)*(1+'Key Information'!$C$16) -> 90677133 | N19: =NPV('Key Information'!$C$16,G20:G$61)*(1+'Key Information'!$C$16) -> 63927854 | O19: =NPV('Key Information'!$C$16,H20:H$61) -> 5.7133347e+08 | P19: =NPV('Key Information'!$C$16,I20:I$61)*(1+'Key Information'!$C$16) -> 4.2192383e+08 | R19: =NPV('Key Information'!$C$16,K20:K$61) -> 1.9996671e+08 | S19: =(M19-R19)+N19+O19+Q19-(L19-P19) -> -3.306615e+08 | T19: =L19*$U$6 -> 1.7361985e+08 | U19: =S19+T19 -> -1.5704165e+08
B20: 2029 | C20: 10 | D20: =D19*(1-VLOOKUP($C19,'Key Information'!$F$8:$I$58,4,FALSE)-VLOOKUP($C19,'Key Information'!$F$8:$I$58,3,FALSE))*(1+'Key Information'!$C$21) -> 2.7138407e+10 | E20: =(E19*VLOOKUP($C19,'Key Information'!$F$8:$I$58,2,FALSE)+E19)*(1-VLOOKUP($C19,'Key Information'!$F$8:$I$58,4,FALSE)-VLOOKUP($C19,'Key Information'!$F$8:$I$58,3,FALSE))*(1+'Key Information'!$C$21) -> 1.1550093e+08 | F20: =(F19*'Key Information'!$C$20+F19)*(1-VLOOKUP($C19,'Key Information'!$F$8:$I$58,4,FALSE)-VLOOKUP($C19,'Key Information'!$F$8:$I$58,3,FALSE)) -> 9696782.3 | G20: ='Key Information'!$C$30*E20 -> 5775046.3 | H20: =D20*VLOOKUP($C20,'Key Information'!$F$8:$I$58,3,FALSE) -> 56990655 | I20: =E20*'Key Information'!$C$44 -> 38115305 | K20: =H20*'Key Information'!$C$45 -> 19946729 | L20: =NPV('Key Information'!$C$16,E21:E$61)*(1+'Key Information'!$C$16) -> 1.1979478e+09 | M20: =NPV('Key Information'!$C$16,F21:F$61)*(1+'Key Information'!$C$16) -> 83409762 | N20: =NPV('Key Information'!$C$16,G21:G$61)*(1+'Key Information'!$C$16) -> 59897392 | O20: =NPV('Key Information'!$C$16,H21:H$61) -> 5.3148282e+08 | P20: =NPV('Key Information'!$C$16,I21:I$61)*(1+'Key Information'!$C$16) -> 3.9532278e+08 | R20: =NPV('Key Information'!$C$16,K21:K$61) -> 1.8601899e+08 | S20: =(M20-R20)+N20+O20+Q20-(L20-P20) -> -3.1385406e+08 | T20: =L20*$U$6 -> 1.6267363e+08 | U20: =S20+T20 -> -1.5118043e+08
B21: 2030 | C21: 11 | D21: =D20*(1-VLOOKUP($C20,'Key Information'!$F$8:$I$58,4,FALSE)-VLOOKUP($C20,'Key Information'!$F$8:$I$58,3,FALSE))*(1+'Key Information'!$C$21) -> 2.4965652e+10 | E21: =(E20*VLOOKUP($C20,'Key Information'!$F$8:$I$58,2,FALSE)+E20)*(1-VLOOKUP($C20,'Key Information'!$F$8:$I$58,4,FALSE)-VLOOKUP($C20,'Key Information'!$F$8:$I$58,3,FALSE))*(1+'Key Information'!$C$21) -> 1.0852217e+08 | F21: =(F20*'Key Information'!$C$20+F20)*(1-VLOOKUP($C20,'Key Information'!$F$8:$I$58,4,FALSE)-VLOOKUP($C20,'Key Information'!$F$8:$I$58,3,FALSE)) -> 9007893.8 | G21: ='Key Information'!$C$30*E21 -> 5426108.6 | H21: =D21*VLOOKUP($C21,'Key Information'!$F$8:$I$58,3,FALSE) -> 54924434 | I21: =E21*'Key Information'!$C$44 -> 35812317 | K21: =H21*'Key Information'!$C$45 -> 19223552 | L21: =NPV('Key Information'!$C$16,E22:E$61)*(1+'Key Information'!$C$16) -> 1.1221084e+09 | M21: =NPV('Key Information'!$C$16,F22:F$61)*(1+'Key Information'!$C$16) -> 76633924 | N21: =NPV('Key Information'!$C$16,G22:G$61)*(1+'Key Information'!$C$16) -> 56105422 | O21: =NPV('Key Information'!$C$16,H22:H$61) -> 4.9250287e+08 | P21: =NPV('Key Information'!$C$16,I22:I$61)*(1+'Key Information'!$C$16) -> 3.7029578e+08 | R21: =NPV('Key Information'!$C$16,K22:K$61) -> 1.72376e+08 | S21: =(M21-R21)+N21+O21+Q21-(L21-P21) -> -2.9894644e+08 | T21: =L21*$U$6 -> 1.5237513e+08 | U21: =S21+T21 -> -1.4657131e+08
B22: 2031 | C22: 12 | D22: =D21*(1-VLOOKUP($C21,'Key Information'!$F$8:$I$58,4,FALSE)-VLOOKUP($C21,'Key Information'!$F$8:$I$58,3,FALSE))*(1+'Key Information'!$C$21) -> 2.293884e+10 | E22: =(E21*VLOOKUP($C21,'Key Information'!$F$8:$I$58,2,FALSE)+E21)*(1-VLOOKUP($C21,'Key Information'!$F$8:$I$58,4,FALSE)-VLOOKUP($C21,'Key Information'!$F$8:$I$58,3,FALSE))*(1+'Key Information'!$C$21) -> 1.0192588e+08 | F22: =(F21*'Key Information'!$C$20+F21)*(1-VLOOKUP($C21,'Key Information'!$F$8:$I$58,4,FALSE)-VLOOKUP($C21,'Key Information'!$F$8:$I$58,3,FALSE)) -> 8357740.1 | G22: ='Key Information'!$C$30*E22 -> 5096293.9 | H22: =D22*VLOOKUP($C22,'Key Information'!$F$8:$I$58,3,FALSE) -> 50465449 | I22: =E22*'Key Information'!$C$44 -> 33635540 | K22: =H22*'Key Information'!$C$45 -> 17662907 | L22: =NPV('Key Information'!$C$16,E23:E$61)*(1+'Key Information'!$C$16) -> 1.050788e+09 | M22: =NPV('Key Information'!$C$16,F23:F$61)*(1+'Key Information'!$C$16) -> 70324469 | N22: =NPV('Key Information'!$C$16,G23:G$61)*(1+'Key Information'!$C$16) -> 52539401 | O22: =NPV('Key Information'!$C$16,H23:H$61) -> 4.5681251e+08 | P22: =NPV('Key Information'!$C$16,I23:I$61)*(1+'Key Information'!$C$16) -> 3.4676005e+08 | R22: =NPV('Key Information'!$C$16,K23:K$61) -> 1.5988438e+08 | S22: =(M22-R22)+N22+O22+Q22-(L22-P22) -> -2.8423598e+08 | T22: =L22*$U$6 -> 1.4269027e+08 | U22: =S22+T22 -> -1.4154571e+08
B23: 2032 | C23: 13 | D23: =D22*(1-VLOOKUP($C22,'Key Information'!$F$8:$I$58,4,FALSE)-VLOOKUP($C22,'Key Information'!$F$8:$I$58,3,FALSE))*(1+'Key Information'!$C$21) -> 2.1053176e+10 | E23: =(E22*VLOOKUP($C22,'Key Information'!$F$8:$I$58,2,FALSE)+E22)*(1-VLOOKUP($C22,'Key Information'!$F$8:$I$58,4,FALSE)-VLOOKUP($C22,'Key Information'!$F$8:$I$58,3,FALSE))*(1+'Key Information'!$C$21) -> 95707337 | F23: =(F22*'Key Information'!$C$20+F22)*(1-VLOOKUP($C22,'Key Information'!$F$8:$I$58,4,FALSE)-VLOOKUP($C22,'Key Information'!$F$8:$I$58,3,FALSE)) -> 7745903.3 | G23: ='Key Information'!$C$30*E23 -> 4785366.8 | H23: =D23*VLOOKUP($C23,'Key Information'!$F$8:$I$58,3,FALSE) -> 48422305 | I23: =E23*'Key Information'!$C$44 -> 31583421 | K23: =H23*'Key Information'!$C$45 -> 16947807 | L23: =NPV('Key Information'!$C$16,E24:E$61)*(1+'Key Information'!$C$16) -> 9.8373311e+08 | M23: =NPV('Key Information'!$C$16,F24:F$61)*(1+'Key Information'!$C$16) -> 64455923 | N23: =NPV('Key Information'!$C$16,G24:G$61)*(1+'Key Information'!$C$16) -> 49186656 | O23: =NPV('Key Information'!$C$16,H24:H$61) -> 4.2209458e+08 | P23: =NPV('Key Information'!$C$16,I24:I$61)*(1+'Key Information'!$C$16) -> 3.2463193e+08 | R23: =NPV('Key Information'!$C$16,K24:K$61) -> 1.477331e+08 | S23: =(M23-R23)+N23+O23+Q23-(L23-P23) -> -2.7109713e+08 | T23: =L23*$U$6 -> 1.3358465e+08 | U23: =S23+T23 -> -1.3751249e+08
... B60: 2069 | C60: 50 | D60: =D59*(1-VLOOKUP($C59,'Key Information'!$F$8:$I$58,4,FALSE)-VLOOKUP($C59,'Key Information'!$F$8:$I$58,3,FALSE))*(1+'Key Information'!$C$21) -> 3.4594012e+08 | E60: =(E59*VLOOKUP($C59,'Key Information'!$F$8:$I$58,2,FALSE)+E59)*(1-VLOOKUP($C59,'Key Information'!$F$8:$I$58,4,FALSE)-VLOOKUP($C59,'Key Information'!$F$8:$I$58,3,FALSE))*(1+'Key Information'!$C$21) -> 10556225 | F60: =(F59*'Key Information'!$C$20+F59)*(1-VLOOKUP($C59,'Key Information'!$F$8:$I$58,4,FALSE)-VLOOKUP($C59,'Key Information'!$F$8:$I$58,3,FALSE)) -> 182610.75 | G60: ='Key Information'!$C$30*E60 -> 527811.23 | H60: =D60*VLOOKUP($C60,'Key Information'!$F$8:$I$58,3,FALSE) -> 1625918.6 | I60: =E60*'Key Information'!$C$44 -> 3483554.1 | K60: =H60*'Key Information'!$C$45 -> 569071.5 | L60: =NPV('Key Information'!$C$16,E61:E$61)*(1+'Key Information'!$C$16) -> 10117657 | M60: =NPV('Key Information'!$C$16,F61:F$61)*(1+'Key Information'!$C$16) -> 160308.32 | N60: =NPV('Key Information'!$C$16,G61:G$61)*(1+'Key Information'!$C$16) -> 505882.87 | O60: =NPV('Key Information'!$C$16,H61:H$61) -> 1372316.3 | P60: =NPV('Key Information'!$C$16,I61:I$61)*(1+'Key Information'!$C$16) -> 3338827 | R60: =NPV('Key Information'!$C$16,K61:K$61) -> 480310.71 | S60: =(M60-R60)+N60+O60+Q60-(L60-P60) -> -5220633.7 | T60: =L60*$U$6 -> 1373913 | U60: =S60+T60 -> -3846720.7
B61: 2070 | C61: 51 | D61: =D60*(1-VLOOKUP($C60,'Key Information'!$F$8:$I$58,4,FALSE)-VLOOKUP($C60,'Key Information'!$F$8:$I$58,3,FALSE))*(1+'Key Information'!$C$21) -> 3.0074166e+08 | E61: =(E60*VLOOKUP($C60,'Key Information'!$F$8:$I$58,2,FALSE)+E60)*(1-VLOOKUP($C60,'Key Information'!$F$8:$I$58,4,FALSE)-VLOOKUP($C60,'Key Information'!$F$8:$I$58,3,FALSE))*(1+'Key Information'!$C$21) -> 10117657 | F61: =(F60*'Key Information'!$C$20+F60)*(1-VLOOKUP($C60,'Key Information'!$F$8:$I$58,4,FALSE)-VLOOKUP($C60,'Key Information'!$F$8:$I$58,3,FALSE)) -> 160308.32 | G61: ='Key Information'!$C$30*E61 -> 505882.87 | H61: =D61*VLOOKUP($C61,'Key Information'!$F$8:$I$58,3,FALSE) -> 1413485.8 | I61: =E61*'Key Information'!$C$44 -> 3338827 | K61: =H61*'Key Information'!$C$45 -> 494720.04 | L61: 0 | M61: 0 | N61: 0 | O61: 0 | P61: 0 | R61: 0 | S61: =(M61-R61)+N61+O61+Q61-(L61-P61) -> 0 | T61: =L61*$U$6 -> 0 | U61: =S61+T61 -> 0

Sheet 1d)
C7: Overall Profitability: | D7: ='Projection (After Recapture)'!T10-'Projection (Before Recapture)'!T10 -> 40137028
